{
 "cells": [
  {
   "cell_type": "code",
   "execution_count": null,
   "metadata": {
    "scrolled": true
   },
   "outputs": [
    {
     "name": "stderr",
     "output_type": "stream",
     "text": [
      "ERROR:root:Internal Python error in the inspect module.\n",
      "Below is the traceback from this internal error.\n",
      "\n",
      "ERROR:root:Internal Python error in the inspect module.\n",
      "Below is the traceback from this internal error.\n",
      "\n",
      "ERROR:root:Internal Python error in the inspect module.\n",
      "Below is the traceback from this internal error.\n",
      "\n"
     ]
    },
    {
     "name": "stdout",
     "output_type": "stream",
     "text": [
      "Traceback (most recent call last):\n",
      "  File \"C:\\Users\\siddh\\miniconda3\\envs\\baseml\\lib\\site-packages\\IPython\\core\\interactiveshell.py\", line 3343, in run_code\n",
      "    exec(code_obj, self.user_global_ns, self.user_ns)\n",
      "  File \"<ipython-input-1-3fe290d0330d>\", line 6, in <module>\n",
      "    from tensorflow.examples.tutorials.mnist import input_data\n",
      "  File \"C:\\Users\\siddh\\miniconda3\\envs\\baseml\\lib\\site-packages\\tensorflow_core\\examples\\tutorials\\mnist\\__init__.py\", line 21, in <module>\n",
      "    from tensorflow.examples.tutorials.mnist import input_data\n",
      "  File \"C:\\Users\\siddh\\miniconda3\\envs\\baseml\\lib\\site-packages\\tensorflow_core\\examples\\tutorials\\mnist\\input_data.py\", line 30, in <module>\n",
      "    from tensorflow.contrib.learn.python.learn.datasets.mnist import read_data_sets\n",
      "  File \"C:\\Users\\siddh\\miniconda3\\envs\\baseml\\lib\\site-packages\\tensorflow\\__init__.py\", line 50, in __getattr__\n",
      "    module = self._load()\n",
      "  File \"C:\\Users\\siddh\\miniconda3\\envs\\baseml\\lib\\site-packages\\tensorflow\\__init__.py\", line 44, in _load\n",
      "    module = _importlib.import_module(self.__name__)\n",
      "  File \"C:\\Users\\siddh\\miniconda3\\envs\\baseml\\lib\\importlib\\__init__.py\", line 126, in import_module\n",
      "    return _bootstrap._gcd_import(name[level:], package, level)\n",
      "  File \"C:\\Users\\siddh\\miniconda3\\envs\\baseml\\lib\\site-packages\\tensorflow_core\\contrib\\__init__.py\", line 39, in <module>\n",
      "    from tensorflow.contrib import compiler\n",
      "  File \"C:\\Users\\siddh\\miniconda3\\envs\\baseml\\lib\\site-packages\\tensorflow_core\\contrib\\compiler\\__init__.py\", line 21, in <module>\n",
      "    from tensorflow.contrib.compiler import jit\n",
      "  File \"C:\\Users\\siddh\\miniconda3\\envs\\baseml\\lib\\site-packages\\tensorflow_core\\contrib\\compiler\\__init__.py\", line 22, in <module>\n",
      "    from tensorflow.contrib.compiler import xla\n",
      "  File \"C:\\Users\\siddh\\miniconda3\\envs\\baseml\\lib\\site-packages\\tensorflow_core\\contrib\\compiler\\xla.py\", line 22, in <module>\n",
      "    from tensorflow.python.estimator import model_fn as model_fn_lib\n",
      "  File \"C:\\Users\\siddh\\miniconda3\\envs\\baseml\\lib\\site-packages\\tensorflow_core\\python\\estimator\\model_fn.py\", line 26, in <module>\n",
      "    from tensorflow_estimator.python.estimator import model_fn\n",
      "  File \"C:\\Users\\siddh\\miniconda3\\envs\\baseml\\lib\\site-packages\\tensorflow_estimator\\__init__.py\", line 10, in <module>\n",
      "    from tensorflow_estimator._api.v1 import estimator\n",
      "  File \"C:\\Users\\siddh\\miniconda3\\envs\\baseml\\lib\\site-packages\\tensorflow_estimator\\_api\\v1\\estimator\\__init__.py\", line 10, in <module>\n",
      "    from tensorflow_estimator._api.v1.estimator import experimental\n",
      "  File \"C:\\Users\\siddh\\miniconda3\\envs\\baseml\\lib\\site-packages\\tensorflow_estimator\\_api\\v1\\estimator\\experimental\\__init__.py\", line 10, in <module>\n",
      "    from tensorflow_estimator.python.estimator.canned.dnn import dnn_logit_fn_builder\n",
      "  File \"C:\\Users\\siddh\\miniconda3\\envs\\baseml\\lib\\site-packages\\tensorflow_estimator\\python\\estimator\\canned\\dnn.py\", line 27, in <module>\n",
      "    from tensorflow_estimator.python.estimator import estimator\n",
      "  File \"C:\\Users\\siddh\\miniconda3\\envs\\baseml\\lib\\site-packages\\tensorflow_estimator\\python\\estimator\\estimator.py\", line 36, in <module>\n",
      "    from tensorflow.python.profiler import trace\n",
      "ImportError: cannot import name 'trace'\n",
      "\n",
      "During handling of the above exception, another exception occurred:\n",
      "\n",
      "Traceback (most recent call last):\n",
      "  File \"C:\\Users\\siddh\\miniconda3\\envs\\baseml\\lib\\site-packages\\IPython\\core\\interactiveshell.py\", line 2044, in showtraceback\n",
      "    stb = value._render_traceback_()\n",
      "AttributeError: 'ImportError' object has no attribute '_render_traceback_'\n",
      "\n",
      "During handling of the above exception, another exception occurred:\n",
      "\n",
      "Traceback (most recent call last):\n",
      "  File \"C:\\Users\\siddh\\miniconda3\\envs\\baseml\\lib\\site-packages\\IPython\\core\\ultratb.py\", line 1169, in get_records\n",
      "    return _fixed_getinnerframes(etb, number_of_lines_of_context, tb_offset)\n",
      "  File \"C:\\Users\\siddh\\miniconda3\\envs\\baseml\\lib\\site-packages\\IPython\\core\\ultratb.py\", line 316, in wrapped\n",
      "    return f(*args, **kwargs)\n",
      "  File \"C:\\Users\\siddh\\miniconda3\\envs\\baseml\\lib\\site-packages\\IPython\\core\\ultratb.py\", line 350, in _fixed_getinnerframes\n",
      "    records = fix_frame_records_filenames(inspect.getinnerframes(etb, context))\n",
      "  File \"C:\\Users\\siddh\\miniconda3\\envs\\baseml\\lib\\inspect.py\", line 1490, in getinnerframes\n",
      "    frameinfo = (tb.tb_frame,) + getframeinfo(tb, context)\n",
      "  File \"C:\\Users\\siddh\\miniconda3\\envs\\baseml\\lib\\inspect.py\", line 1448, in getframeinfo\n",
      "    filename = getsourcefile(frame) or getfile(frame)\n",
      "  File \"C:\\Users\\siddh\\miniconda3\\envs\\baseml\\lib\\inspect.py\", line 696, in getsourcefile\n",
      "    if getattr(getmodule(object, filename), '__loader__', None) is not None:\n",
      "  File \"C:\\Users\\siddh\\miniconda3\\envs\\baseml\\lib\\inspect.py\", line 733, in getmodule\n",
      "    if ismodule(module) and hasattr(module, '__file__'):\n",
      "  File \"C:\\Users\\siddh\\miniconda3\\envs\\baseml\\lib\\site-packages\\tensorflow\\__init__.py\", line 50, in __getattr__\n",
      "    module = self._load()\n",
      "  File \"C:\\Users\\siddh\\miniconda3\\envs\\baseml\\lib\\site-packages\\tensorflow\\__init__.py\", line 44, in _load\n",
      "    module = _importlib.import_module(self.__name__)\n",
      "  File \"C:\\Users\\siddh\\miniconda3\\envs\\baseml\\lib\\importlib\\__init__.py\", line 126, in import_module\n",
      "    return _bootstrap._gcd_import(name[level:], package, level)\n",
      "  File \"<frozen importlib._bootstrap>\", line 994, in _gcd_import\n",
      "  File \"<frozen importlib._bootstrap>\", line 971, in _find_and_load\n",
      "  File \"<frozen importlib._bootstrap>\", line 953, in _find_and_load_unlocked\n",
      "ModuleNotFoundError: No module named 'tensorflow_core.estimator'\n",
      "Traceback (most recent call last):\n",
      "  File \"C:\\Users\\siddh\\miniconda3\\envs\\baseml\\lib\\site-packages\\IPython\\core\\interactiveshell.py\", line 3343, in run_code\n",
      "    exec(code_obj, self.user_global_ns, self.user_ns)\n",
      "  File \"<ipython-input-1-3fe290d0330d>\", line 6, in <module>\n",
      "    from tensorflow.examples.tutorials.mnist import input_data\n",
      "  File \"C:\\Users\\siddh\\miniconda3\\envs\\baseml\\lib\\site-packages\\tensorflow_core\\examples\\tutorials\\mnist\\__init__.py\", line 21, in <module>\n",
      "    from tensorflow.examples.tutorials.mnist import input_data\n",
      "  File \"C:\\Users\\siddh\\miniconda3\\envs\\baseml\\lib\\site-packages\\tensorflow_core\\examples\\tutorials\\mnist\\input_data.py\", line 30, in <module>\n",
      "    from tensorflow.contrib.learn.python.learn.datasets.mnist import read_data_sets\n",
      "  File \"C:\\Users\\siddh\\miniconda3\\envs\\baseml\\lib\\site-packages\\tensorflow\\__init__.py\", line 50, in __getattr__\n",
      "    module = self._load()\n",
      "  File \"C:\\Users\\siddh\\miniconda3\\envs\\baseml\\lib\\site-packages\\tensorflow\\__init__.py\", line 44, in _load\n",
      "    module = _importlib.import_module(self.__name__)\n",
      "  File \"C:\\Users\\siddh\\miniconda3\\envs\\baseml\\lib\\importlib\\__init__.py\", line 126, in import_module\n",
      "    return _bootstrap._gcd_import(name[level:], package, level)\n",
      "  File \"C:\\Users\\siddh\\miniconda3\\envs\\baseml\\lib\\site-packages\\tensorflow_core\\contrib\\__init__.py\", line 39, in <module>\n",
      "    from tensorflow.contrib import compiler\n",
      "  File \"C:\\Users\\siddh\\miniconda3\\envs\\baseml\\lib\\site-packages\\tensorflow_core\\contrib\\compiler\\__init__.py\", line 21, in <module>\n",
      "    from tensorflow.contrib.compiler import jit\n",
      "  File \"C:\\Users\\siddh\\miniconda3\\envs\\baseml\\lib\\site-packages\\tensorflow_core\\contrib\\compiler\\__init__.py\", line 22, in <module>\n",
      "    from tensorflow.contrib.compiler import xla\n",
      "  File \"C:\\Users\\siddh\\miniconda3\\envs\\baseml\\lib\\site-packages\\tensorflow_core\\contrib\\compiler\\xla.py\", line 22, in <module>\n",
      "    from tensorflow.python.estimator import model_fn as model_fn_lib\n",
      "  File \"C:\\Users\\siddh\\miniconda3\\envs\\baseml\\lib\\site-packages\\tensorflow_core\\python\\estimator\\model_fn.py\", line 26, in <module>\n",
      "    from tensorflow_estimator.python.estimator import model_fn\n",
      "  File \"C:\\Users\\siddh\\miniconda3\\envs\\baseml\\lib\\site-packages\\tensorflow_estimator\\__init__.py\", line 10, in <module>\n",
      "    from tensorflow_estimator._api.v1 import estimator\n",
      "  File \"C:\\Users\\siddh\\miniconda3\\envs\\baseml\\lib\\site-packages\\tensorflow_estimator\\_api\\v1\\estimator\\__init__.py\", line 10, in <module>\n",
      "    from tensorflow_estimator._api.v1.estimator import experimental\n",
      "  File \"C:\\Users\\siddh\\miniconda3\\envs\\baseml\\lib\\site-packages\\tensorflow_estimator\\_api\\v1\\estimator\\experimental\\__init__.py\", line 10, in <module>\n",
      "    from tensorflow_estimator.python.estimator.canned.dnn import dnn_logit_fn_builder\n",
      "  File \"C:\\Users\\siddh\\miniconda3\\envs\\baseml\\lib\\site-packages\\tensorflow_estimator\\python\\estimator\\canned\\dnn.py\", line 27, in <module>\n",
      "    from tensorflow_estimator.python.estimator import estimator\n",
      "  File \"C:\\Users\\siddh\\miniconda3\\envs\\baseml\\lib\\site-packages\\tensorflow_estimator\\python\\estimator\\estimator.py\", line 36, in <module>\n",
      "    from tensorflow.python.profiler import trace\n",
      "ImportError: cannot import name 'trace'\n",
      "\n",
      "During handling of the above exception, another exception occurred:\n",
      "\n",
      "Traceback (most recent call last):\n",
      "  File \"C:\\Users\\siddh\\miniconda3\\envs\\baseml\\lib\\site-packages\\IPython\\core\\interactiveshell.py\", line 2044, in showtraceback\n",
      "    stb = value._render_traceback_()\n",
      "AttributeError: 'ImportError' object has no attribute '_render_traceback_'\n",
      "\n",
      "During handling of the above exception, another exception occurred:\n",
      "\n",
      "Traceback (most recent call last):\n",
      "  File \"C:\\Users\\siddh\\miniconda3\\envs\\baseml\\lib\\site-packages\\IPython\\core\\interactiveshell.py\", line 3263, in run_ast_nodes\n",
      "    if (await self.run_code(code, result,  async_=asy)):\n",
      "  File \"C:\\Users\\siddh\\miniconda3\\envs\\baseml\\lib\\site-packages\\IPython\\core\\interactiveshell.py\", line 3360, in run_code\n",
      "    self.showtraceback(running_compiled_code=True)\n",
      "  File \"C:\\Users\\siddh\\miniconda3\\envs\\baseml\\lib\\site-packages\\IPython\\core\\interactiveshell.py\", line 2047, in showtraceback\n",
      "    value, tb, tb_offset=tb_offset)\n",
      "  File \"C:\\Users\\siddh\\miniconda3\\envs\\baseml\\lib\\site-packages\\IPython\\core\\ultratb.py\", line 1436, in structured_traceback\n",
      "    self, etype, value, tb, tb_offset, number_of_lines_of_context)\n",
      "  File \"C:\\Users\\siddh\\miniconda3\\envs\\baseml\\lib\\site-packages\\IPython\\core\\ultratb.py\", line 1336, in structured_traceback\n",
      "    self, etype, value, tb, tb_offset, number_of_lines_of_context\n",
      "  File \"C:\\Users\\siddh\\miniconda3\\envs\\baseml\\lib\\site-packages\\IPython\\core\\ultratb.py\", line 1193, in structured_traceback\n",
      "    tb_offset)\n",
      "  File \"C:\\Users\\siddh\\miniconda3\\envs\\baseml\\lib\\site-packages\\IPython\\core\\ultratb.py\", line 1150, in format_exception_as_a_whole\n",
      "    last_unique, recursion_repeat = find_recursion(orig_etype, evalue, records)\n",
      "  File \"C:\\Users\\siddh\\miniconda3\\envs\\baseml\\lib\\site-packages\\IPython\\core\\ultratb.py\", line 451, in find_recursion\n",
      "    return len(records), 0\n",
      "TypeError: object of type 'NoneType' has no len()\n",
      "\n",
      "During handling of the above exception, another exception occurred:\n",
      "\n",
      "Traceback (most recent call last):\n",
      "  File \"C:\\Users\\siddh\\miniconda3\\envs\\baseml\\lib\\site-packages\\IPython\\core\\interactiveshell.py\", line 2044, in showtraceback\n",
      "    stb = value._render_traceback_()\n",
      "AttributeError: 'TypeError' object has no attribute '_render_traceback_'\n",
      "\n",
      "During handling of the above exception, another exception occurred:\n",
      "\n",
      "Traceback (most recent call last):\n",
      "  File \"C:\\Users\\siddh\\miniconda3\\envs\\baseml\\lib\\site-packages\\IPython\\core\\ultratb.py\", line 1169, in get_records\n",
      "    return _fixed_getinnerframes(etb, number_of_lines_of_context, tb_offset)\n",
      "  File \"C:\\Users\\siddh\\miniconda3\\envs\\baseml\\lib\\site-packages\\IPython\\core\\ultratb.py\", line 316, in wrapped\n",
      "    return f(*args, **kwargs)\n",
      "  File \"C:\\Users\\siddh\\miniconda3\\envs\\baseml\\lib\\site-packages\\IPython\\core\\ultratb.py\", line 350, in _fixed_getinnerframes\n",
      "    records = fix_frame_records_filenames(inspect.getinnerframes(etb, context))\n",
      "  File \"C:\\Users\\siddh\\miniconda3\\envs\\baseml\\lib\\inspect.py\", line 1490, in getinnerframes\n",
      "    frameinfo = (tb.tb_frame,) + getframeinfo(tb, context)\n",
      "  File \"C:\\Users\\siddh\\miniconda3\\envs\\baseml\\lib\\inspect.py\", line 1448, in getframeinfo\n",
      "    filename = getsourcefile(frame) or getfile(frame)\n",
      "  File \"C:\\Users\\siddh\\miniconda3\\envs\\baseml\\lib\\inspect.py\", line 696, in getsourcefile\n",
      "    if getattr(getmodule(object, filename), '__loader__', None) is not None:\n",
      "  File \"C:\\Users\\siddh\\miniconda3\\envs\\baseml\\lib\\inspect.py\", line 733, in getmodule\n",
      "    if ismodule(module) and hasattr(module, '__file__'):\n",
      "  File \"C:\\Users\\siddh\\miniconda3\\envs\\baseml\\lib\\site-packages\\tensorflow\\__init__.py\", line 50, in __getattr__\n",
      "    module = self._load()\n",
      "  File \"C:\\Users\\siddh\\miniconda3\\envs\\baseml\\lib\\site-packages\\tensorflow\\__init__.py\", line 44, in _load\n",
      "    module = _importlib.import_module(self.__name__)\n",
      "  File \"C:\\Users\\siddh\\miniconda3\\envs\\baseml\\lib\\importlib\\__init__.py\", line 126, in import_module\n",
      "    return _bootstrap._gcd_import(name[level:], package, level)\n",
      "  File \"<frozen importlib._bootstrap>\", line 994, in _gcd_import\n",
      "  File \"<frozen importlib._bootstrap>\", line 971, in _find_and_load\n",
      "  File \"<frozen importlib._bootstrap>\", line 953, in _find_and_load_unlocked\n",
      "ModuleNotFoundError: No module named 'tensorflow_core.estimator'\n",
      "Traceback (most recent call last):\n",
      "  File \"C:\\Users\\siddh\\miniconda3\\envs\\baseml\\lib\\site-packages\\IPython\\core\\interactiveshell.py\", line 3343, in run_code\n",
      "    exec(code_obj, self.user_global_ns, self.user_ns)\n",
      "  File \"<ipython-input-1-3fe290d0330d>\", line 6, in <module>\n",
      "    from tensorflow.examples.tutorials.mnist import input_data\n",
      "  File \"C:\\Users\\siddh\\miniconda3\\envs\\baseml\\lib\\site-packages\\tensorflow_core\\examples\\tutorials\\mnist\\__init__.py\", line 21, in <module>\n",
      "    from tensorflow.examples.tutorials.mnist import input_data\n",
      "  File \"C:\\Users\\siddh\\miniconda3\\envs\\baseml\\lib\\site-packages\\tensorflow_core\\examples\\tutorials\\mnist\\input_data.py\", line 30, in <module>\n",
      "    from tensorflow.contrib.learn.python.learn.datasets.mnist import read_data_sets\n",
      "  File \"C:\\Users\\siddh\\miniconda3\\envs\\baseml\\lib\\site-packages\\tensorflow\\__init__.py\", line 50, in __getattr__\n",
      "    module = self._load()\n",
      "  File \"C:\\Users\\siddh\\miniconda3\\envs\\baseml\\lib\\site-packages\\tensorflow\\__init__.py\", line 44, in _load\n",
      "    module = _importlib.import_module(self.__name__)\n",
      "  File \"C:\\Users\\siddh\\miniconda3\\envs\\baseml\\lib\\importlib\\__init__.py\", line 126, in import_module\n",
      "    return _bootstrap._gcd_import(name[level:], package, level)\n",
      "  File \"C:\\Users\\siddh\\miniconda3\\envs\\baseml\\lib\\site-packages\\tensorflow_core\\contrib\\__init__.py\", line 39, in <module>\n",
      "    from tensorflow.contrib import compiler\n",
      "  File \"C:\\Users\\siddh\\miniconda3\\envs\\baseml\\lib\\site-packages\\tensorflow_core\\contrib\\compiler\\__init__.py\", line 21, in <module>\n",
      "    from tensorflow.contrib.compiler import jit\n",
      "  File \"C:\\Users\\siddh\\miniconda3\\envs\\baseml\\lib\\site-packages\\tensorflow_core\\contrib\\compiler\\__init__.py\", line 22, in <module>\n",
      "    from tensorflow.contrib.compiler import xla\n",
      "  File \"C:\\Users\\siddh\\miniconda3\\envs\\baseml\\lib\\site-packages\\tensorflow_core\\contrib\\compiler\\xla.py\", line 22, in <module>\n",
      "    from tensorflow.python.estimator import model_fn as model_fn_lib\n",
      "  File \"C:\\Users\\siddh\\miniconda3\\envs\\baseml\\lib\\site-packages\\tensorflow_core\\python\\estimator\\model_fn.py\", line 26, in <module>\n",
      "    from tensorflow_estimator.python.estimator import model_fn\n",
      "  File \"C:\\Users\\siddh\\miniconda3\\envs\\baseml\\lib\\site-packages\\tensorflow_estimator\\__init__.py\", line 10, in <module>\n",
      "    from tensorflow_estimator._api.v1 import estimator\n",
      "  File \"C:\\Users\\siddh\\miniconda3\\envs\\baseml\\lib\\site-packages\\tensorflow_estimator\\_api\\v1\\estimator\\__init__.py\", line 10, in <module>\n",
      "    from tensorflow_estimator._api.v1.estimator import experimental\n",
      "  File \"C:\\Users\\siddh\\miniconda3\\envs\\baseml\\lib\\site-packages\\tensorflow_estimator\\_api\\v1\\estimator\\experimental\\__init__.py\", line 10, in <module>\n",
      "    from tensorflow_estimator.python.estimator.canned.dnn import dnn_logit_fn_builder\n",
      "  File \"C:\\Users\\siddh\\miniconda3\\envs\\baseml\\lib\\site-packages\\tensorflow_estimator\\python\\estimator\\canned\\dnn.py\", line 27, in <module>\n",
      "    from tensorflow_estimator.python.estimator import estimator\n",
      "  File \"C:\\Users\\siddh\\miniconda3\\envs\\baseml\\lib\\site-packages\\tensorflow_estimator\\python\\estimator\\estimator.py\", line 36, in <module>\n",
      "    from tensorflow.python.profiler import trace\n",
      "ImportError: cannot import name 'trace'\n",
      "\n",
      "During handling of the above exception, another exception occurred:\n",
      "\n",
      "Traceback (most recent call last):\n",
      "  File \"C:\\Users\\siddh\\miniconda3\\envs\\baseml\\lib\\site-packages\\IPython\\core\\interactiveshell.py\", line 2044, in showtraceback\n",
      "    stb = value._render_traceback_()\n",
      "AttributeError: 'ImportError' object has no attribute '_render_traceback_'\n",
      "\n",
      "During handling of the above exception, another exception occurred:\n",
      "\n",
      "Traceback (most recent call last):\n",
      "  File \"C:\\Users\\siddh\\miniconda3\\envs\\baseml\\lib\\site-packages\\IPython\\core\\interactiveshell.py\", line 3263, in run_ast_nodes\n",
      "    if (await self.run_code(code, result,  async_=asy)):\n",
      "  File \"C:\\Users\\siddh\\miniconda3\\envs\\baseml\\lib\\site-packages\\IPython\\core\\interactiveshell.py\", line 3360, in run_code\n",
      "    self.showtraceback(running_compiled_code=True)\n",
      "  File \"C:\\Users\\siddh\\miniconda3\\envs\\baseml\\lib\\site-packages\\IPython\\core\\interactiveshell.py\", line 2047, in showtraceback\n",
      "    value, tb, tb_offset=tb_offset)\n",
      "  File \"C:\\Users\\siddh\\miniconda3\\envs\\baseml\\lib\\site-packages\\IPython\\core\\ultratb.py\", line 1436, in structured_traceback\n",
      "    self, etype, value, tb, tb_offset, number_of_lines_of_context)\n",
      "  File \"C:\\Users\\siddh\\miniconda3\\envs\\baseml\\lib\\site-packages\\IPython\\core\\ultratb.py\", line 1336, in structured_traceback\n",
      "    self, etype, value, tb, tb_offset, number_of_lines_of_context\n",
      "  File \"C:\\Users\\siddh\\miniconda3\\envs\\baseml\\lib\\site-packages\\IPython\\core\\ultratb.py\", line 1193, in structured_traceback\n",
      "    tb_offset)\n",
      "  File \"C:\\Users\\siddh\\miniconda3\\envs\\baseml\\lib\\site-packages\\IPython\\core\\ultratb.py\", line 1150, in format_exception_as_a_whole\n",
      "    last_unique, recursion_repeat = find_recursion(orig_etype, evalue, records)\n",
      "  File \"C:\\Users\\siddh\\miniconda3\\envs\\baseml\\lib\\site-packages\\IPython\\core\\ultratb.py\", line 451, in find_recursion\n",
      "    return len(records), 0\n",
      "TypeError: object of type 'NoneType' has no len()\n",
      "\n",
      "During handling of the above exception, another exception occurred:\n",
      "\n",
      "Traceback (most recent call last):\n",
      "  File \"C:\\Users\\siddh\\miniconda3\\envs\\baseml\\lib\\site-packages\\IPython\\core\\interactiveshell.py\", line 2044, in showtraceback\n",
      "    stb = value._render_traceback_()\n",
      "AttributeError: 'TypeError' object has no attribute '_render_traceback_'\n",
      "\n",
      "During handling of the above exception, another exception occurred:\n",
      "\n",
      "Traceback (most recent call last):\n",
      "  File \"C:\\Users\\siddh\\miniconda3\\envs\\baseml\\lib\\site-packages\\IPython\\core\\interactiveshell.py\", line 2895, in _run_cell\n",
      "    return runner(coro)\n",
      "  File \"C:\\Users\\siddh\\miniconda3\\envs\\baseml\\lib\\site-packages\\IPython\\core\\async_helpers.py\", line 68, in _pseudo_sync_runner\n",
      "    coro.send(None)\n",
      "  File \"C:\\Users\\siddh\\miniconda3\\envs\\baseml\\lib\\site-packages\\IPython\\core\\interactiveshell.py\", line 3072, in run_cell_async\n",
      "    interactivity=interactivity, compiler=compiler, result=result)\n",
      "  File \"C:\\Users\\siddh\\miniconda3\\envs\\baseml\\lib\\site-packages\\IPython\\core\\interactiveshell.py\", line 3282, in run_ast_nodes\n",
      "    self.showtraceback()\n",
      "  File \"C:\\Users\\siddh\\miniconda3\\envs\\baseml\\lib\\site-packages\\IPython\\core\\interactiveshell.py\", line 2047, in showtraceback\n",
      "    value, tb, tb_offset=tb_offset)\n",
      "  File \"C:\\Users\\siddh\\miniconda3\\envs\\baseml\\lib\\site-packages\\IPython\\core\\ultratb.py\", line 1436, in structured_traceback\n",
      "    self, etype, value, tb, tb_offset, number_of_lines_of_context)\n",
      "  File \"C:\\Users\\siddh\\miniconda3\\envs\\baseml\\lib\\site-packages\\IPython\\core\\ultratb.py\", line 1336, in structured_traceback\n",
      "    self, etype, value, tb, tb_offset, number_of_lines_of_context\n",
      "  File \"C:\\Users\\siddh\\miniconda3\\envs\\baseml\\lib\\site-packages\\IPython\\core\\ultratb.py\", line 1211, in structured_traceback\n",
      "    chained_exceptions_tb_offset)\n",
      "  File \"C:\\Users\\siddh\\miniconda3\\envs\\baseml\\lib\\site-packages\\IPython\\core\\ultratb.py\", line 1150, in format_exception_as_a_whole\n",
      "    last_unique, recursion_repeat = find_recursion(orig_etype, evalue, records)\n",
      "  File \"C:\\Users\\siddh\\miniconda3\\envs\\baseml\\lib\\site-packages\\IPython\\core\\ultratb.py\", line 451, in find_recursion\n",
      "    return len(records), 0\n",
      "TypeError: object of type 'NoneType' has no len()\n",
      "\n",
      "During handling of the above exception, another exception occurred:\n",
      "\n",
      "Traceback (most recent call last):\n",
      "  File \"C:\\Users\\siddh\\miniconda3\\envs\\baseml\\lib\\site-packages\\IPython\\core\\interactiveshell.py\", line 2044, in showtraceback\n",
      "    stb = value._render_traceback_()\n",
      "AttributeError: 'TypeError' object has no attribute '_render_traceback_'\n",
      "\n",
      "During handling of the above exception, another exception occurred:\n",
      "\n",
      "Traceback (most recent call last):\n",
      "  File \"C:\\Users\\siddh\\miniconda3\\envs\\baseml\\lib\\site-packages\\IPython\\core\\ultratb.py\", line 1169, in get_records\n",
      "    return _fixed_getinnerframes(etb, number_of_lines_of_context, tb_offset)\n",
      "  File \"C:\\Users\\siddh\\miniconda3\\envs\\baseml\\lib\\site-packages\\IPython\\core\\ultratb.py\", line 316, in wrapped\n",
      "    return f(*args, **kwargs)\n",
      "  File \"C:\\Users\\siddh\\miniconda3\\envs\\baseml\\lib\\site-packages\\IPython\\core\\ultratb.py\", line 350, in _fixed_getinnerframes\n",
      "    records = fix_frame_records_filenames(inspect.getinnerframes(etb, context))\n",
      "  File \"C:\\Users\\siddh\\miniconda3\\envs\\baseml\\lib\\inspect.py\", line 1490, in getinnerframes\n",
      "    frameinfo = (tb.tb_frame,) + getframeinfo(tb, context)\n",
      "  File \"C:\\Users\\siddh\\miniconda3\\envs\\baseml\\lib\\inspect.py\", line 1448, in getframeinfo\n",
      "    filename = getsourcefile(frame) or getfile(frame)\n",
      "  File \"C:\\Users\\siddh\\miniconda3\\envs\\baseml\\lib\\inspect.py\", line 696, in getsourcefile\n",
      "    if getattr(getmodule(object, filename), '__loader__', None) is not None:\n",
      "  File \"C:\\Users\\siddh\\miniconda3\\envs\\baseml\\lib\\inspect.py\", line 733, in getmodule\n",
      "    if ismodule(module) and hasattr(module, '__file__'):\n",
      "  File \"C:\\Users\\siddh\\miniconda3\\envs\\baseml\\lib\\site-packages\\tensorflow\\__init__.py\", line 50, in __getattr__\n",
      "    module = self._load()\n",
      "  File \"C:\\Users\\siddh\\miniconda3\\envs\\baseml\\lib\\site-packages\\tensorflow\\__init__.py\", line 44, in _load\n",
      "    module = _importlib.import_module(self.__name__)\n",
      "  File \"C:\\Users\\siddh\\miniconda3\\envs\\baseml\\lib\\importlib\\__init__.py\", line 126, in import_module\n",
      "    return _bootstrap._gcd_import(name[level:], package, level)\n",
      "  File \"<frozen importlib._bootstrap>\", line 994, in _gcd_import\n",
      "  File \"<frozen importlib._bootstrap>\", line 971, in _find_and_load\n",
      "  File \"<frozen importlib._bootstrap>\", line 953, in _find_and_load_unlocked\n",
      "ModuleNotFoundError: No module named 'tensorflow_core.estimator'\n"
     ]
    }
   ],
   "source": [
    "from __future__ import division, print_function, absolute_import\n",
    "\n",
    "import tensorflow as tf #tf=1.1.x\n",
    "\n",
    "# Import MNIST data\n",
    "from tensorflow.examples.tutorials.mnist import input_data\n",
    "mnist = input_data.read_data_sets(\"/tmp/data/\", one_hot=True)"
   ]
  },
  {
   "cell_type": "code",
   "execution_count": 1,
   "metadata": {},
   "outputs": [
    {
     "name": "stdout",
     "output_type": "stream",
     "text": [
      "ERROR! Session/line number was not unique in database. History logging moved to new session 41\n"
     ]
    }
   ],
   "source": [
    "# Training Parameters\n",
    "learning_rate = 0.001\n",
    "num_steps = 100  #number of epochs\n",
    "batch_size = 128\n",
    "display_step = 1\n",
    "\n",
    "# Network Parameters\n",
    "num_input = 784 # MNIST data input (img shape: 28*28)\n",
    "num_classes = 10 # MNIST total classes (0-9 digits)\n",
    "dropout = 0.50 # Dropout, probability to keep units\n",
    "\n",
    "# tf Graph input\n",
    "X = tf.placeholder(tf.float32, [None, num_input])\n",
    "Y = tf.placeholder(tf.float32, [None, num_classes])\n",
    "keep_prob = tf.placeholder(tf.float32) # dropout (keep probability)"
   ]
  },
  {
   "cell_type": "code",
   "execution_count": 2,
   "metadata": {},
   "outputs": [],
   "source": [
    "# Store layers weight & bias\n",
    "\n",
    "#X.W\n",
    "weights = {\n",
    "    # 5x5 conv, 1 input, 32 outputs\n",
    "    'wc1': tf.Variable(tf.random_normal([5, 5, 1, 32])),\n",
    "    # 5x5 conv, 32 inputs, 64 outputs\n",
    "    'wc2': tf.Variable(tf.random_normal([5, 5, 32, 64])),\n",
    "    # fully connected, 7*7*64 inputs, 1024 outputs\n",
    "    'wd1': tf.Variable(tf.random_normal([7*7*64, 1024])),\n",
    "    # 1024 inputs, 10 outputs (class prediction)\n",
    "    'out': tf.Variable(tf.random_normal([1024, num_classes]))\n",
    "}\n",
    "\n",
    "# +b\n",
    "biases = {\n",
    "    'bc1': tf.Variable(tf.random_normal([32])),\n",
    "    'bc2': tf.Variable(tf.random_normal([64])),\n",
    "    'bd1': tf.Variable(tf.random_normal([1024])),\n",
    "    'out': tf.Variable(tf.random_normal([num_classes]))\n",
    "}"
   ]
  },
  {
   "cell_type": "code",
   "execution_count": 3,
   "metadata": {},
   "outputs": [],
   "source": [
    "# Create some wrappers for simplicity\n",
    "def conv2d(x, W, b, strides=1):\n",
    "    # Conv2D wrapper, with bias and relu activation\n",
    "    x = tf.nn.conv2d(x, W, strides=[1, strides, strides, 1], padding='SAME')\n",
    "    x = tf.nn.bias_add(x, b)\n",
    "    return tf.nn.relu(x)\n",
    "\n",
    "\n",
    "def maxpool2d(x, k=2):\n",
    "    # MaxPool2D wrapper\n",
    "    return tf.nn.max_pool(x, ksize=[1, k, k, 1], strides=[1, k, k, 1],\n",
    "                          padding='SAME')\n",
    "\n",
    "\n",
    "# Create model\n",
    "def conv_net(x, weights, biases, dropout):\n",
    "    # MNIST data input is a 1-D vector of 784 features (28*28 pixels)\n",
    "    # Reshape to match picture format [Height x Width x Channel]\n",
    "    # Tensor input become 4-D: [Batch Size, Height, Width, Channel]\n",
    "    x = tf.reshape(x, shape=[-1, 28, 28, 1])\n",
    "\n",
    "    # Convolution Layer\n",
    "    conv1 = conv2d(x, weights['wc1'], biases['bc1'])\n",
    "    # Max Pooling (down-sampling)\n",
    "    conv1 = maxpool2d(conv1, k=2)\n",
    "\n",
    "    # Convolution Layer\n",
    "    conv2 = conv2d(conv1, weights['wc2'], biases['bc2'])\n",
    "    # Max Pooling (down-sampling)\n",
    "    conv2 = maxpool2d(conv2, k=2)\n",
    "\n",
    "    # Fully connected layer\n",
    "    # Reshape conv2 output to fit fully connected layer input\n",
    "    fc1 = tf.reshape(conv2, [-1, weights['wd1'].get_shape().as_list()[0]])\n",
    "    fc1 = tf.add(tf.matmul(fc1, weights['wd1']), biases['bd1'])\n",
    "    fc1 = tf.nn.relu(fc1)\n",
    "    # Apply Dropout\n",
    "    fc1 = tf.nn.dropout(fc1, dropout)\n",
    "\n",
    "    # Output, class prediction\n",
    "    # y = summation (w1 +b1, w2+b2)\n",
    "    out = tf.add(tf.matmul(fc1, weights['out']), biases['out'])\n",
    "    return out"
   ]
  },
  {
   "cell_type": "code",
   "execution_count": 4,
   "metadata": {},
   "outputs": [
    {
     "name": "stdout",
     "output_type": "stream",
     "text": [
      "WARNING:tensorflow:From <ipython-input-3-842137d78044>:38: calling dropout (from tensorflow.python.ops.nn_ops) with keep_prob is deprecated and will be removed in a future version.\n",
      "Instructions for updating:\n",
      "Please use `rate` instead of `keep_prob`. Rate should be set to `rate = 1 - keep_prob`.\n"
     ]
    },
    {
     "name": "stderr",
     "output_type": "stream",
     "text": [
      "WARNING:tensorflow:From <ipython-input-3-842137d78044>:38: calling dropout (from tensorflow.python.ops.nn_ops) with keep_prob is deprecated and will be removed in a future version.\n",
      "Instructions for updating:\n",
      "Please use `rate` instead of `keep_prob`. Rate should be set to `rate = 1 - keep_prob`.\n"
     ]
    },
    {
     "name": "stdout",
     "output_type": "stream",
     "text": [
      "WARNING:tensorflow:From <ipython-input-4-01a1334f1495>:7: softmax_cross_entropy_with_logits (from tensorflow.python.ops.nn_ops) is deprecated and will be removed in a future version.\n",
      "Instructions for updating:\n",
      "\n",
      "Future major versions of TensorFlow will allow gradients to flow\n",
      "into the labels input on backprop by default.\n",
      "\n",
      "See `tf.nn.softmax_cross_entropy_with_logits_v2`.\n",
      "\n"
     ]
    },
    {
     "name": "stderr",
     "output_type": "stream",
     "text": [
      "WARNING:tensorflow:From <ipython-input-4-01a1334f1495>:7: softmax_cross_entropy_with_logits (from tensorflow.python.ops.nn_ops) is deprecated and will be removed in a future version.\n",
      "Instructions for updating:\n",
      "\n",
      "Future major versions of TensorFlow will allow gradients to flow\n",
      "into the labels input on backprop by default.\n",
      "\n",
      "See `tf.nn.softmax_cross_entropy_with_logits_v2`.\n",
      "\n"
     ]
    }
   ],
   "source": [
    "\n",
    "# Construct model\n",
    "logits = conv_net(X, weights, biases, keep_prob)\n",
    "prediction = tf.nn.softmax(logits)\n",
    "\n",
    "# Define loss and optimizer\n",
    "loss_op = tf.reduce_mean(tf.nn.softmax_cross_entropy_with_logits(\n",
    "    logits=logits, labels=Y))\n",
    "optimizer = tf.train.AdamOptimizer(learning_rate=learning_rate)\n",
    "train_op = optimizer.minimize(loss_op)\n",
    "\n",
    "\n",
    "# Evaluate model\n",
    "correct_pred = tf.equal(tf.argmax(prediction, 1), tf.argmax(Y, 1))\n",
    "accuracy = tf.reduce_mean(tf.cast(correct_pred, tf.float32))\n",
    "\n",
    "# Initialize the variables (i.e. assign their default value)\n",
    "init = tf.global_variables_initializer()"
   ]
  },
  {
   "cell_type": "code",
   "execution_count": null,
   "metadata": {
    "scrolled": true
   },
   "outputs": [
    {
     "name": "stderr",
     "output_type": "stream",
     "text": [
      "ERROR:root:Internal Python error in the inspect module.\n",
      "Below is the traceback from this internal error.\n",
      "\n",
      "ERROR:root:Internal Python error in the inspect module.\n",
      "Below is the traceback from this internal error.\n",
      "\n",
      "ERROR:root:Internal Python error in the inspect module.\n",
      "Below is the traceback from this internal error.\n",
      "\n"
     ]
    },
    {
     "name": "stdout",
     "output_type": "stream",
     "text": [
      "Traceback (most recent call last):\n",
      "  File \"C:\\Users\\siddh\\miniconda3\\envs\\baseml\\lib\\site-packages\\IPython\\core\\interactiveshell.py\", line 3343, in run_code\n",
      "    exec(code_obj, self.user_global_ns, self.user_ns)\n",
      "  File \"<ipython-input-5-a03c7549d5b5>\", line 8, in <module>\n",
      "    batch_x, batch_y = mnist.train.next_batch(batch_size)\n",
      "NameError: name 'mnist' is not defined\n",
      "\n",
      "During handling of the above exception, another exception occurred:\n",
      "\n",
      "Traceback (most recent call last):\n",
      "  File \"C:\\Users\\siddh\\miniconda3\\envs\\baseml\\lib\\site-packages\\IPython\\core\\interactiveshell.py\", line 2044, in showtraceback\n",
      "    stb = value._render_traceback_()\n",
      "AttributeError: 'NameError' object has no attribute '_render_traceback_'\n",
      "\n",
      "During handling of the above exception, another exception occurred:\n",
      "\n",
      "Traceback (most recent call last):\n",
      "  File \"C:\\Users\\siddh\\miniconda3\\envs\\baseml\\lib\\site-packages\\IPython\\core\\ultratb.py\", line 1169, in get_records\n",
      "    return _fixed_getinnerframes(etb, number_of_lines_of_context, tb_offset)\n",
      "  File \"C:\\Users\\siddh\\miniconda3\\envs\\baseml\\lib\\site-packages\\IPython\\core\\ultratb.py\", line 316, in wrapped\n",
      "    return f(*args, **kwargs)\n",
      "  File \"C:\\Users\\siddh\\miniconda3\\envs\\baseml\\lib\\site-packages\\IPython\\core\\ultratb.py\", line 350, in _fixed_getinnerframes\n",
      "    records = fix_frame_records_filenames(inspect.getinnerframes(etb, context))\n",
      "  File \"C:\\Users\\siddh\\miniconda3\\envs\\baseml\\lib\\inspect.py\", line 1490, in getinnerframes\n",
      "    frameinfo = (tb.tb_frame,) + getframeinfo(tb, context)\n",
      "  File \"C:\\Users\\siddh\\miniconda3\\envs\\baseml\\lib\\inspect.py\", line 1448, in getframeinfo\n",
      "    filename = getsourcefile(frame) or getfile(frame)\n",
      "  File \"C:\\Users\\siddh\\miniconda3\\envs\\baseml\\lib\\inspect.py\", line 696, in getsourcefile\n",
      "    if getattr(getmodule(object, filename), '__loader__', None) is not None:\n",
      "  File \"C:\\Users\\siddh\\miniconda3\\envs\\baseml\\lib\\inspect.py\", line 733, in getmodule\n",
      "    if ismodule(module) and hasattr(module, '__file__'):\n",
      "  File \"C:\\Users\\siddh\\miniconda3\\envs\\baseml\\lib\\site-packages\\tensorflow\\__init__.py\", line 50, in __getattr__\n",
      "    module = self._load()\n",
      "  File \"C:\\Users\\siddh\\miniconda3\\envs\\baseml\\lib\\site-packages\\tensorflow\\__init__.py\", line 44, in _load\n",
      "    module = _importlib.import_module(self.__name__)\n",
      "  File \"C:\\Users\\siddh\\miniconda3\\envs\\baseml\\lib\\importlib\\__init__.py\", line 126, in import_module\n",
      "    return _bootstrap._gcd_import(name[level:], package, level)\n",
      "  File \"<frozen importlib._bootstrap>\", line 994, in _gcd_import\n",
      "  File \"<frozen importlib._bootstrap>\", line 971, in _find_and_load\n",
      "  File \"<frozen importlib._bootstrap>\", line 953, in _find_and_load_unlocked\n",
      "ModuleNotFoundError: No module named 'tensorflow_core.estimator'\n",
      "Traceback (most recent call last):\n",
      "  File \"C:\\Users\\siddh\\miniconda3\\envs\\baseml\\lib\\site-packages\\IPython\\core\\interactiveshell.py\", line 3343, in run_code\n",
      "    exec(code_obj, self.user_global_ns, self.user_ns)\n",
      "  File \"<ipython-input-5-a03c7549d5b5>\", line 8, in <module>\n",
      "    batch_x, batch_y = mnist.train.next_batch(batch_size)\n",
      "NameError: name 'mnist' is not defined\n",
      "\n",
      "During handling of the above exception, another exception occurred:\n",
      "\n",
      "Traceback (most recent call last):\n",
      "  File \"C:\\Users\\siddh\\miniconda3\\envs\\baseml\\lib\\site-packages\\IPython\\core\\interactiveshell.py\", line 2044, in showtraceback\n",
      "    stb = value._render_traceback_()\n",
      "AttributeError: 'NameError' object has no attribute '_render_traceback_'\n",
      "\n",
      "During handling of the above exception, another exception occurred:\n",
      "\n",
      "Traceback (most recent call last):\n",
      "  File \"C:\\Users\\siddh\\miniconda3\\envs\\baseml\\lib\\site-packages\\IPython\\core\\interactiveshell.py\", line 3263, in run_ast_nodes\n",
      "    if (await self.run_code(code, result,  async_=asy)):\n",
      "  File \"C:\\Users\\siddh\\miniconda3\\envs\\baseml\\lib\\site-packages\\IPython\\core\\interactiveshell.py\", line 3360, in run_code\n",
      "    self.showtraceback(running_compiled_code=True)\n",
      "  File \"C:\\Users\\siddh\\miniconda3\\envs\\baseml\\lib\\site-packages\\IPython\\core\\interactiveshell.py\", line 2047, in showtraceback\n",
      "    value, tb, tb_offset=tb_offset)\n",
      "  File \"C:\\Users\\siddh\\miniconda3\\envs\\baseml\\lib\\site-packages\\IPython\\core\\ultratb.py\", line 1436, in structured_traceback\n",
      "    self, etype, value, tb, tb_offset, number_of_lines_of_context)\n",
      "  File \"C:\\Users\\siddh\\miniconda3\\envs\\baseml\\lib\\site-packages\\IPython\\core\\ultratb.py\", line 1336, in structured_traceback\n",
      "    self, etype, value, tb, tb_offset, number_of_lines_of_context\n",
      "  File \"C:\\Users\\siddh\\miniconda3\\envs\\baseml\\lib\\site-packages\\IPython\\core\\ultratb.py\", line 1193, in structured_traceback\n",
      "    tb_offset)\n",
      "  File \"C:\\Users\\siddh\\miniconda3\\envs\\baseml\\lib\\site-packages\\IPython\\core\\ultratb.py\", line 1150, in format_exception_as_a_whole\n",
      "    last_unique, recursion_repeat = find_recursion(orig_etype, evalue, records)\n",
      "  File \"C:\\Users\\siddh\\miniconda3\\envs\\baseml\\lib\\site-packages\\IPython\\core\\ultratb.py\", line 451, in find_recursion\n",
      "    return len(records), 0\n",
      "TypeError: object of type 'NoneType' has no len()\n",
      "\n",
      "During handling of the above exception, another exception occurred:\n",
      "\n",
      "Traceback (most recent call last):\n",
      "  File \"C:\\Users\\siddh\\miniconda3\\envs\\baseml\\lib\\site-packages\\IPython\\core\\interactiveshell.py\", line 2044, in showtraceback\n",
      "    stb = value._render_traceback_()\n",
      "AttributeError: 'TypeError' object has no attribute '_render_traceback_'\n",
      "\n",
      "During handling of the above exception, another exception occurred:\n",
      "\n",
      "Traceback (most recent call last):\n",
      "  File \"C:\\Users\\siddh\\miniconda3\\envs\\baseml\\lib\\site-packages\\IPython\\core\\ultratb.py\", line 1169, in get_records\n",
      "    return _fixed_getinnerframes(etb, number_of_lines_of_context, tb_offset)\n",
      "  File \"C:\\Users\\siddh\\miniconda3\\envs\\baseml\\lib\\site-packages\\IPython\\core\\ultratb.py\", line 316, in wrapped\n",
      "    return f(*args, **kwargs)\n",
      "  File \"C:\\Users\\siddh\\miniconda3\\envs\\baseml\\lib\\site-packages\\IPython\\core\\ultratb.py\", line 350, in _fixed_getinnerframes\n",
      "    records = fix_frame_records_filenames(inspect.getinnerframes(etb, context))\n",
      "  File \"C:\\Users\\siddh\\miniconda3\\envs\\baseml\\lib\\inspect.py\", line 1490, in getinnerframes\n",
      "    frameinfo = (tb.tb_frame,) + getframeinfo(tb, context)\n",
      "  File \"C:\\Users\\siddh\\miniconda3\\envs\\baseml\\lib\\inspect.py\", line 1448, in getframeinfo\n",
      "    filename = getsourcefile(frame) or getfile(frame)\n",
      "  File \"C:\\Users\\siddh\\miniconda3\\envs\\baseml\\lib\\inspect.py\", line 696, in getsourcefile\n",
      "    if getattr(getmodule(object, filename), '__loader__', None) is not None:\n",
      "  File \"C:\\Users\\siddh\\miniconda3\\envs\\baseml\\lib\\inspect.py\", line 733, in getmodule\n",
      "    if ismodule(module) and hasattr(module, '__file__'):\n",
      "  File \"C:\\Users\\siddh\\miniconda3\\envs\\baseml\\lib\\site-packages\\tensorflow\\__init__.py\", line 50, in __getattr__\n",
      "    module = self._load()\n",
      "  File \"C:\\Users\\siddh\\miniconda3\\envs\\baseml\\lib\\site-packages\\tensorflow\\__init__.py\", line 44, in _load\n",
      "    module = _importlib.import_module(self.__name__)\n",
      "  File \"C:\\Users\\siddh\\miniconda3\\envs\\baseml\\lib\\importlib\\__init__.py\", line 126, in import_module\n",
      "    return _bootstrap._gcd_import(name[level:], package, level)\n",
      "  File \"<frozen importlib._bootstrap>\", line 994, in _gcd_import\n",
      "  File \"<frozen importlib._bootstrap>\", line 971, in _find_and_load\n",
      "  File \"<frozen importlib._bootstrap>\", line 953, in _find_and_load_unlocked\n",
      "ModuleNotFoundError: No module named 'tensorflow_core.estimator'\n",
      "Traceback (most recent call last):\n",
      "  File \"C:\\Users\\siddh\\miniconda3\\envs\\baseml\\lib\\site-packages\\IPython\\core\\interactiveshell.py\", line 3343, in run_code\n",
      "    exec(code_obj, self.user_global_ns, self.user_ns)\n",
      "  File \"<ipython-input-5-a03c7549d5b5>\", line 8, in <module>\n",
      "    batch_x, batch_y = mnist.train.next_batch(batch_size)\n",
      "NameError: name 'mnist' is not defined\n",
      "\n",
      "During handling of the above exception, another exception occurred:\n",
      "\n",
      "Traceback (most recent call last):\n",
      "  File \"C:\\Users\\siddh\\miniconda3\\envs\\baseml\\lib\\site-packages\\IPython\\core\\interactiveshell.py\", line 2044, in showtraceback\n",
      "    stb = value._render_traceback_()\n",
      "AttributeError: 'NameError' object has no attribute '_render_traceback_'\n",
      "\n",
      "During handling of the above exception, another exception occurred:\n",
      "\n",
      "Traceback (most recent call last):\n",
      "  File \"C:\\Users\\siddh\\miniconda3\\envs\\baseml\\lib\\site-packages\\IPython\\core\\interactiveshell.py\", line 3263, in run_ast_nodes\n",
      "    if (await self.run_code(code, result,  async_=asy)):\n",
      "  File \"C:\\Users\\siddh\\miniconda3\\envs\\baseml\\lib\\site-packages\\IPython\\core\\interactiveshell.py\", line 3360, in run_code\n",
      "    self.showtraceback(running_compiled_code=True)\n",
      "  File \"C:\\Users\\siddh\\miniconda3\\envs\\baseml\\lib\\site-packages\\IPython\\core\\interactiveshell.py\", line 2047, in showtraceback\n",
      "    value, tb, tb_offset=tb_offset)\n",
      "  File \"C:\\Users\\siddh\\miniconda3\\envs\\baseml\\lib\\site-packages\\IPython\\core\\ultratb.py\", line 1436, in structured_traceback\n",
      "    self, etype, value, tb, tb_offset, number_of_lines_of_context)\n",
      "  File \"C:\\Users\\siddh\\miniconda3\\envs\\baseml\\lib\\site-packages\\IPython\\core\\ultratb.py\", line 1336, in structured_traceback\n",
      "    self, etype, value, tb, tb_offset, number_of_lines_of_context\n",
      "  File \"C:\\Users\\siddh\\miniconda3\\envs\\baseml\\lib\\site-packages\\IPython\\core\\ultratb.py\", line 1193, in structured_traceback\n",
      "    tb_offset)\n",
      "  File \"C:\\Users\\siddh\\miniconda3\\envs\\baseml\\lib\\site-packages\\IPython\\core\\ultratb.py\", line 1150, in format_exception_as_a_whole\n",
      "    last_unique, recursion_repeat = find_recursion(orig_etype, evalue, records)\n",
      "  File \"C:\\Users\\siddh\\miniconda3\\envs\\baseml\\lib\\site-packages\\IPython\\core\\ultratb.py\", line 451, in find_recursion\n",
      "    return len(records), 0\n",
      "TypeError: object of type 'NoneType' has no len()\n",
      "\n",
      "During handling of the above exception, another exception occurred:\n",
      "\n",
      "Traceback (most recent call last):\n",
      "  File \"C:\\Users\\siddh\\miniconda3\\envs\\baseml\\lib\\site-packages\\IPython\\core\\interactiveshell.py\", line 2044, in showtraceback\n",
      "    stb = value._render_traceback_()\n",
      "AttributeError: 'TypeError' object has no attribute '_render_traceback_'\n",
      "\n",
      "During handling of the above exception, another exception occurred:\n",
      "\n",
      "Traceback (most recent call last):\n",
      "  File \"C:\\Users\\siddh\\miniconda3\\envs\\baseml\\lib\\site-packages\\IPython\\core\\interactiveshell.py\", line 2895, in _run_cell\n",
      "    return runner(coro)\n",
      "  File \"C:\\Users\\siddh\\miniconda3\\envs\\baseml\\lib\\site-packages\\IPython\\core\\async_helpers.py\", line 68, in _pseudo_sync_runner\n",
      "    coro.send(None)\n",
      "  File \"C:\\Users\\siddh\\miniconda3\\envs\\baseml\\lib\\site-packages\\IPython\\core\\interactiveshell.py\", line 3072, in run_cell_async\n",
      "    interactivity=interactivity, compiler=compiler, result=result)\n",
      "  File \"C:\\Users\\siddh\\miniconda3\\envs\\baseml\\lib\\site-packages\\IPython\\core\\interactiveshell.py\", line 3282, in run_ast_nodes\n",
      "    self.showtraceback()\n",
      "  File \"C:\\Users\\siddh\\miniconda3\\envs\\baseml\\lib\\site-packages\\IPython\\core\\interactiveshell.py\", line 2047, in showtraceback\n",
      "    value, tb, tb_offset=tb_offset)\n",
      "  File \"C:\\Users\\siddh\\miniconda3\\envs\\baseml\\lib\\site-packages\\IPython\\core\\ultratb.py\", line 1436, in structured_traceback\n",
      "    self, etype, value, tb, tb_offset, number_of_lines_of_context)\n",
      "  File \"C:\\Users\\siddh\\miniconda3\\envs\\baseml\\lib\\site-packages\\IPython\\core\\ultratb.py\", line 1336, in structured_traceback\n",
      "    self, etype, value, tb, tb_offset, number_of_lines_of_context\n",
      "  File \"C:\\Users\\siddh\\miniconda3\\envs\\baseml\\lib\\site-packages\\IPython\\core\\ultratb.py\", line 1211, in structured_traceback\n",
      "    chained_exceptions_tb_offset)\n",
      "  File \"C:\\Users\\siddh\\miniconda3\\envs\\baseml\\lib\\site-packages\\IPython\\core\\ultratb.py\", line 1150, in format_exception_as_a_whole\n",
      "    last_unique, recursion_repeat = find_recursion(orig_etype, evalue, records)\n",
      "  File \"C:\\Users\\siddh\\miniconda3\\envs\\baseml\\lib\\site-packages\\IPython\\core\\ultratb.py\", line 451, in find_recursion\n",
      "    return len(records), 0\n",
      "TypeError: object of type 'NoneType' has no len()\n",
      "\n",
      "During handling of the above exception, another exception occurred:\n",
      "\n",
      "Traceback (most recent call last):\n",
      "  File \"C:\\Users\\siddh\\miniconda3\\envs\\baseml\\lib\\site-packages\\IPython\\core\\interactiveshell.py\", line 2044, in showtraceback\n",
      "    stb = value._render_traceback_()\n",
      "AttributeError: 'TypeError' object has no attribute '_render_traceback_'\n",
      "\n",
      "During handling of the above exception, another exception occurred:\n",
      "\n",
      "Traceback (most recent call last):\n",
      "  File \"C:\\Users\\siddh\\miniconda3\\envs\\baseml\\lib\\site-packages\\IPython\\core\\ultratb.py\", line 1169, in get_records\n",
      "    return _fixed_getinnerframes(etb, number_of_lines_of_context, tb_offset)\n",
      "  File \"C:\\Users\\siddh\\miniconda3\\envs\\baseml\\lib\\site-packages\\IPython\\core\\ultratb.py\", line 316, in wrapped\n",
      "    return f(*args, **kwargs)\n",
      "  File \"C:\\Users\\siddh\\miniconda3\\envs\\baseml\\lib\\site-packages\\IPython\\core\\ultratb.py\", line 350, in _fixed_getinnerframes\n",
      "    records = fix_frame_records_filenames(inspect.getinnerframes(etb, context))\n",
      "  File \"C:\\Users\\siddh\\miniconda3\\envs\\baseml\\lib\\inspect.py\", line 1490, in getinnerframes\n",
      "    frameinfo = (tb.tb_frame,) + getframeinfo(tb, context)\n",
      "  File \"C:\\Users\\siddh\\miniconda3\\envs\\baseml\\lib\\inspect.py\", line 1448, in getframeinfo\n",
      "    filename = getsourcefile(frame) or getfile(frame)\n",
      "  File \"C:\\Users\\siddh\\miniconda3\\envs\\baseml\\lib\\inspect.py\", line 696, in getsourcefile\n",
      "    if getattr(getmodule(object, filename), '__loader__', None) is not None:\n",
      "  File \"C:\\Users\\siddh\\miniconda3\\envs\\baseml\\lib\\inspect.py\", line 733, in getmodule\n",
      "    if ismodule(module) and hasattr(module, '__file__'):\n",
      "  File \"C:\\Users\\siddh\\miniconda3\\envs\\baseml\\lib\\site-packages\\tensorflow\\__init__.py\", line 50, in __getattr__\n",
      "    module = self._load()\n",
      "  File \"C:\\Users\\siddh\\miniconda3\\envs\\baseml\\lib\\site-packages\\tensorflow\\__init__.py\", line 44, in _load\n",
      "    module = _importlib.import_module(self.__name__)\n",
      "  File \"C:\\Users\\siddh\\miniconda3\\envs\\baseml\\lib\\importlib\\__init__.py\", line 126, in import_module\n",
      "    return _bootstrap._gcd_import(name[level:], package, level)\n",
      "  File \"<frozen importlib._bootstrap>\", line 994, in _gcd_import\n",
      "  File \"<frozen importlib._bootstrap>\", line 971, in _find_and_load\n",
      "  File \"<frozen importlib._bootstrap>\", line 953, in _find_and_load_unlocked\n",
      "ModuleNotFoundError: No module named 'tensorflow_core.estimator'\n"
     ]
    }
   ],
   "source": [
    "# Start training\n",
    "with tf.Session() as sess:\n",
    "\n",
    "    # Run the initializer\n",
    "    sess.run(init)\n",
    "\n",
    "    for step in range(1, num_steps+1):\n",
    "        batch_x, batch_y = mnist.train.next_batch(batch_size)\n",
    "        # Run optimization op (backprop)\n",
    "        sess.run(train_op, feed_dict={X: batch_x, Y: batch_y, keep_prob: dropout})\n",
    "        if step % display_step == 0 or step == 1:\n",
    "            # Calculate batch loss and accuracy\n",
    "            loss, acc = sess.run([loss_op, accuracy], feed_dict={X: batch_x,\n",
    "                                                                 Y: batch_y,\n",
    "                                                                 keep_prob: 1.0})\n",
    "            print(\"Step \" + str(step) + \", Minibatch Loss= \" + \\\n",
    "                  \"{:.4f}\".format(loss) + \", Training Accuracy= \" + \\\n",
    "                  \"{:.3f}\".format(acc))\n",
    "\n",
    "    print(\"Training Finished!\")\n",
    "\n",
    "    # Calculate accuracy for 256 MNIST test images\n",
    "    print(\"Testing Accuracy:\", \\\n",
    "        sess.run(accuracy, feed_dict={X: mnist.test.images[:256],\n",
    "                                      Y: mnist.test.labels[:256],\n",
    "                                      keep_prob: 1.0}))\n"
   ]
  },
  {
   "cell_type": "code",
   "execution_count": null,
   "metadata": {},
   "outputs": [],
   "source": []
  },
  {
   "cell_type": "code",
   "execution_count": null,
   "metadata": {},
   "outputs": [],
   "source": []
  }
 ],
 "metadata": {
  "kernelspec": {
   "display_name": "Python 3",
   "language": "python",
   "name": "python3"
  },
  "language_info": {
   "codemirror_mode": {
    "name": "ipython",
    "version": 3
   },
   "file_extension": ".py",
   "mimetype": "text/x-python",
   "name": "python",
   "nbconvert_exporter": "python",
   "pygments_lexer": "ipython3",
   "version": "3.6.13"
  }
 },
 "nbformat": 4,
 "nbformat_minor": 1
}
